2025-02-07 23:14:23,835 - INFO - Found credentials in shared credentials file: ~/.aws/credentials
2025-02-07 23:14:30,913 - INFO - Found credentials in shared credentials file: ~/.aws/credentials
2025-02-07 23:14:31,213 - INFO - [31m[1mWARNING: This is a development server. Do not use it in a production deployment. Use a production WSGI server instead.[0m
 * Running on all addresses (0.0.0.0)
 * Running on http://127.0.0.1:8080
 * Running on http://192.168.40.213:8080
2025-02-07 23:14:31,213 - INFO - [33mPress CTRL+C to quit[0m
2025-02-07 23:18:07,238 - INFO - Found credentials in shared credentials file: ~/.aws/credentials
2025-02-07 23:18:07,621 - INFO - [31m[1mWARNING: This is a development server. Do not use it in a production deployment. Use a production WSGI server instead.[0m
 * Running on all addresses (0.0.0.0)
 * Running on http://127.0.0.1:8080
 * Running on http://192.168.40.213:8080
2025-02-07 23:18:07,621 - INFO - [33mPress CTRL+C to quit[0m
2025-02-07 23:18:58,625 - INFO - Found credentials in shared credentials file: ~/.aws/credentials
2025-02-07 23:18:58,929 - INFO - [31m[1mWARNING: This is a development server. Do not use it in a production deployment. Use a production WSGI server instead.[0m
 * Running on all addresses (0.0.0.0)
 * Running on http://127.0.0.1:8080
 * Running on http://192.168.40.213:8080
2025-02-07 23:18:58,929 - INFO - [33mPress CTRL+C to quit[0m
2025-02-07 23:19:06,866 - INFO - 127.0.0.1 - - [07/Feb/2025 23:19:06] "[33mGET / HTTP/1.1[0m" 404 -
2025-02-07 23:20:11,693 - INFO - Found credentials in shared credentials file: ~/.aws/credentials
2025-02-07 23:20:50,236 - INFO - Found credentials in shared credentials file: ~/.aws/credentials
2025-02-07 23:20:50,546 - INFO - [31m[1mWARNING: This is a development server. Do not use it in a production deployment. Use a production WSGI server instead.[0m
 * Running on all addresses (0.0.0.0)
 * Running on http://127.0.0.1:8080
 * Running on http://192.168.40.213:8080
2025-02-07 23:20:50,546 - INFO - [33mPress CTRL+C to quit[0m
2025-02-07 23:21:00,592 - WARNING - Received empty user message.
2025-02-07 23:21:00,592 - INFO - 127.0.0.1 - - [07/Feb/2025 23:21:00] "[31m[1mPOST /api/chat HTTP/1.1[0m" 400 -
2025-02-07 23:24:18,610 - WARNING - Received empty user message.
2025-02-07 23:24:18,610 - INFO - 127.0.0.1 - - [07/Feb/2025 23:24:18] "[31m[1mPOST /api/chat HTTP/1.1[0m" 400 -
2025-02-07 23:33:33,818 - INFO - Found credentials in shared credentials file: ~/.aws/credentials
2025-02-07 23:33:34,232 - INFO - [31m[1mWARNING: This is a development server. Do not use it in a production deployment. Use a production WSGI server instead.[0m
 * Running on all addresses (0.0.0.0)
 * Running on http://127.0.0.1:8080
 * Running on http://192.168.40.213:8080
2025-02-07 23:33:34,232 - INFO - [33mPress CTRL+C to quit[0m
2025-02-07 23:33:40,661 - INFO - 127.0.0.1 - - [07/Feb/2025 23:33:40] "[33mGET / HTTP/1.1[0m" 404 -
2025-02-07 23:53:52,598 - INFO - Found credentials in shared credentials file: ~/.aws/credentials
2025-02-07 23:53:52,962 - INFO - [31m[1mWARNING: This is a development server. Do not use it in a production deployment. Use a production WSGI server instead.[0m
 * Running on all addresses (0.0.0.0)
 * Running on http://127.0.0.1:8080
 * Running on http://192.168.40.213:8080
2025-02-07 23:53:52,963 - INFO - [33mPress CTRL+C to quit[0m
2025-02-07 23:54:54,936 - INFO - User [127.0.0.1] Input: Hello
2025-02-07 23:54:54,936 - ERROR - Exception on /api/chat [POST]
Traceback (most recent call last):
  File "/Users/RyanPierce/Documents/GitHub/Resume/ryanapierce.github.io/assets/projects/about_me_chatbot/backend/application.py", line 68, in chat
    response = openai.ChatCompletion.create(
               ^^^^^^^^^^^^^^^^^^^^^^^^^^^^^
  File "/Users/RyanPierce/Documents/GitHub/Resume/ryanapierce.github.io/assets/projects/about_me_chatbot/backend/venv/lib/python3.11/site-packages/openai/lib/_old_api.py", line 39, in __call__
    raise APIRemovedInV1(symbol=self._symbol)
openai.lib._old_api.APIRemovedInV1: 

You tried to access openai.ChatCompletion, but this is no longer supported in openai>=1.0.0 - see the README at https://github.com/openai/openai-python for the API.

You can run `openai migrate` to automatically upgrade your codebase to use the 1.0.0 interface. 

Alternatively, you can pin your installation to the old version, e.g. `pip install openai==0.28`

A detailed migration guide is available here: https://github.com/openai/openai-python/discussions/742


During handling of the above exception, another exception occurred:

Traceback (most recent call last):
  File "/Users/RyanPierce/Documents/GitHub/Resume/ryanapierce.github.io/assets/projects/about_me_chatbot/backend/venv/lib/python3.11/site-packages/flask/app.py", line 1511, in wsgi_app
    response = self.full_dispatch_request()
               ^^^^^^^^^^^^^^^^^^^^^^^^^^^^
  File "/Users/RyanPierce/Documents/GitHub/Resume/ryanapierce.github.io/assets/projects/about_me_chatbot/backend/venv/lib/python3.11/site-packages/flask/app.py", line 919, in full_dispatch_request
    rv = self.handle_user_exception(e)
         ^^^^^^^^^^^^^^^^^^^^^^^^^^^^^
  File "/Users/RyanPierce/Documents/GitHub/Resume/ryanapierce.github.io/assets/projects/about_me_chatbot/backend/venv/lib/python3.11/site-packages/flask_cors/extension.py", line 194, in wrapped_function
    return cors_after_request(app.make_response(f(*args, **kwargs)))
                                                ^^^^^^^^^^^^^^^^^^
  File "/Users/RyanPierce/Documents/GitHub/Resume/ryanapierce.github.io/assets/projects/about_me_chatbot/backend/venv/lib/python3.11/site-packages/flask/app.py", line 917, in full_dispatch_request
    rv = self.dispatch_request()
         ^^^^^^^^^^^^^^^^^^^^^^^
  File "/Users/RyanPierce/Documents/GitHub/Resume/ryanapierce.github.io/assets/projects/about_me_chatbot/backend/venv/lib/python3.11/site-packages/flask/app.py", line 902, in dispatch_request
    return self.ensure_sync(self.view_functions[rule.endpoint])(**view_args)  # type: ignore[no-any-return]
           ^^^^^^^^^^^^^^^^^^^^^^^^^^^^^^^^^^^^^^^^^^^^^^^^^^^^^^^^^^^^^^^^^
  File "/Users/RyanPierce/Documents/GitHub/Resume/ryanapierce.github.io/assets/projects/about_me_chatbot/backend/application.py", line 82, in chat
    except openai.error.OpenAIError as e:
           ^^^^^^^^^^^^
AttributeError: module 'openai' has no attribute 'error'
2025-02-07 23:54:54,939 - INFO - 127.0.0.1 - - [07/Feb/2025 23:54:54] "[35m[1mPOST /api/chat HTTP/1.1[0m" 500 -
2025-02-07 23:55:42,205 - INFO - User [127.0.0.1] Input: Hello
2025-02-07 23:55:42,206 - ERROR - Exception on /api/chat [POST]
Traceback (most recent call last):
  File "/Users/RyanPierce/Documents/GitHub/Resume/ryanapierce.github.io/assets/projects/about_me_chatbot/backend/application.py", line 68, in chat
    response = openai.ChatCompletion.create(
               ^^^^^^^^^^^^^^^^^^^^^^^^^^^^^
  File "/Users/RyanPierce/Documents/GitHub/Resume/ryanapierce.github.io/assets/projects/about_me_chatbot/backend/venv/lib/python3.11/site-packages/openai/lib/_old_api.py", line 39, in __call__
    raise APIRemovedInV1(symbol=self._symbol)
openai.lib._old_api.APIRemovedInV1: 

You tried to access openai.ChatCompletion, but this is no longer supported in openai>=1.0.0 - see the README at https://github.com/openai/openai-python for the API.

You can run `openai migrate` to automatically upgrade your codebase to use the 1.0.0 interface. 

Alternatively, you can pin your installation to the old version, e.g. `pip install openai==0.28`

A detailed migration guide is available here: https://github.com/openai/openai-python/discussions/742


During handling of the above exception, another exception occurred:

Traceback (most recent call last):
  File "/Users/RyanPierce/Documents/GitHub/Resume/ryanapierce.github.io/assets/projects/about_me_chatbot/backend/venv/lib/python3.11/site-packages/flask/app.py", line 1511, in wsgi_app
    response = self.full_dispatch_request()
               ^^^^^^^^^^^^^^^^^^^^^^^^^^^^
  File "/Users/RyanPierce/Documents/GitHub/Resume/ryanapierce.github.io/assets/projects/about_me_chatbot/backend/venv/lib/python3.11/site-packages/flask/app.py", line 919, in full_dispatch_request
    rv = self.handle_user_exception(e)
         ^^^^^^^^^^^^^^^^^^^^^^^^^^^^^
  File "/Users/RyanPierce/Documents/GitHub/Resume/ryanapierce.github.io/assets/projects/about_me_chatbot/backend/venv/lib/python3.11/site-packages/flask_cors/extension.py", line 194, in wrapped_function
    return cors_after_request(app.make_response(f(*args, **kwargs)))
                                                ^^^^^^^^^^^^^^^^^^
  File "/Users/RyanPierce/Documents/GitHub/Resume/ryanapierce.github.io/assets/projects/about_me_chatbot/backend/venv/lib/python3.11/site-packages/flask/app.py", line 917, in full_dispatch_request
    rv = self.dispatch_request()
         ^^^^^^^^^^^^^^^^^^^^^^^
  File "/Users/RyanPierce/Documents/GitHub/Resume/ryanapierce.github.io/assets/projects/about_me_chatbot/backend/venv/lib/python3.11/site-packages/flask/app.py", line 902, in dispatch_request
    return self.ensure_sync(self.view_functions[rule.endpoint])(**view_args)  # type: ignore[no-any-return]
           ^^^^^^^^^^^^^^^^^^^^^^^^^^^^^^^^^^^^^^^^^^^^^^^^^^^^^^^^^^^^^^^^^
  File "/Users/RyanPierce/Documents/GitHub/Resume/ryanapierce.github.io/assets/projects/about_me_chatbot/backend/application.py", line 82, in chat
    except openai.error.OpenAIError as e:
           ^^^^^^^^^^^^
AttributeError: module 'openai' has no attribute 'error'
2025-02-07 23:55:42,207 - INFO - 127.0.0.1 - - [07/Feb/2025 23:55:42] "[35m[1mPOST /api/chat HTTP/1.1[0m" 500 -
2025-02-08 00:04:28,379 - INFO - User [127.0.0.1] Input: Hello
2025-02-08 00:04:28,380 - ERROR - Exception on /api/chat [POST]
Traceback (most recent call last):
  File "/Users/RyanPierce/Documents/GitHub/Resume/ryanapierce.github.io/assets/projects/about_me_chatbot/backend/application.py", line 68, in chat
    response = openai.ChatCompletion.create(
               ^^^^^^^^^^^^^^^^^^^^^^^^^^^^^
  File "/Users/RyanPierce/Documents/GitHub/Resume/ryanapierce.github.io/assets/projects/about_me_chatbot/backend/venv/lib/python3.11/site-packages/openai/lib/_old_api.py", line 39, in __call__
    raise APIRemovedInV1(symbol=self._symbol)
openai.lib._old_api.APIRemovedInV1: 

You tried to access openai.ChatCompletion, but this is no longer supported in openai>=1.0.0 - see the README at https://github.com/openai/openai-python for the API.

You can run `openai migrate` to automatically upgrade your codebase to use the 1.0.0 interface. 

Alternatively, you can pin your installation to the old version, e.g. `pip install openai==0.28`

A detailed migration guide is available here: https://github.com/openai/openai-python/discussions/742


During handling of the above exception, another exception occurred:

Traceback (most recent call last):
  File "/Users/RyanPierce/Documents/GitHub/Resume/ryanapierce.github.io/assets/projects/about_me_chatbot/backend/venv/lib/python3.11/site-packages/flask/app.py", line 1511, in wsgi_app
    response = self.full_dispatch_request()
               ^^^^^^^^^^^^^^^^^^^^^^^^^^^^
  File "/Users/RyanPierce/Documents/GitHub/Resume/ryanapierce.github.io/assets/projects/about_me_chatbot/backend/venv/lib/python3.11/site-packages/flask/app.py", line 919, in full_dispatch_request
    rv = self.handle_user_exception(e)
         ^^^^^^^^^^^^^^^^^^^^^^^^^^^^^
  File "/Users/RyanPierce/Documents/GitHub/Resume/ryanapierce.github.io/assets/projects/about_me_chatbot/backend/venv/lib/python3.11/site-packages/flask_cors/extension.py", line 194, in wrapped_function
    return cors_after_request(app.make_response(f(*args, **kwargs)))
                                                ^^^^^^^^^^^^^^^^^^
  File "/Users/RyanPierce/Documents/GitHub/Resume/ryanapierce.github.io/assets/projects/about_me_chatbot/backend/venv/lib/python3.11/site-packages/flask/app.py", line 917, in full_dispatch_request
    rv = self.dispatch_request()
         ^^^^^^^^^^^^^^^^^^^^^^^
  File "/Users/RyanPierce/Documents/GitHub/Resume/ryanapierce.github.io/assets/projects/about_me_chatbot/backend/venv/lib/python3.11/site-packages/flask/app.py", line 902, in dispatch_request
    return self.ensure_sync(self.view_functions[rule.endpoint])(**view_args)  # type: ignore[no-any-return]
           ^^^^^^^^^^^^^^^^^^^^^^^^^^^^^^^^^^^^^^^^^^^^^^^^^^^^^^^^^^^^^^^^^
  File "/Users/RyanPierce/Documents/GitHub/Resume/ryanapierce.github.io/assets/projects/about_me_chatbot/backend/application.py", line 82, in chat
    except openai.error.OpenAIError as e:
           ^^^^^^^^^^^^
AttributeError: module 'openai' has no attribute 'error'
2025-02-08 00:04:28,382 - INFO - 127.0.0.1 - - [08/Feb/2025 00:04:28] "[35m[1mPOST /api/chat HTTP/1.1[0m" 500 -
2025-02-08 00:07:13,110 - INFO - Found credentials in shared credentials file: ~/.aws/credentials
2025-02-08 00:07:13,853 - INFO - [31m[1mWARNING: This is a development server. Do not use it in a production deployment. Use a production WSGI server instead.[0m
 * Running on all addresses (0.0.0.0)
 * Running on http://127.0.0.1:8080
 * Running on http://192.168.40.213:8080
2025-02-08 00:07:13,854 - INFO - [33mPress CTRL+C to quit[0m
2025-02-08 00:07:13,855 - INFO -  * Restarting with stat
2025-02-08 00:07:14,415 - INFO - Found credentials in shared credentials file: ~/.aws/credentials
2025-02-08 00:07:15,087 - WARNING -  * Debugger is active!
2025-02-08 00:07:15,256 - INFO -  * Debugger PIN: 822-635-497
2025-02-08 00:07:32,851 - INFO - User [127.0.0.1] Input: Hello
2025-02-08 00:07:32,857 - INFO - 127.0.0.1 - - [08/Feb/2025 00:07:32] "[35m[1mPOST /api/chat HTTP/1.1[0m" 500 -
2025-02-08 00:08:19,167 - INFO -  * Detected change in '/Users/RyanPierce/Documents/GitHub/Resume/ryanapierce.github.io/assets/projects/about_me_chatbot/backend/application.py', reloading
2025-02-08 00:08:19,273 - INFO -  * Restarting with stat
2025-02-08 00:10:39,271 - INFO - Found credentials in shared credentials file: ~/.aws/credentials
2025-02-08 00:10:39,669 - INFO - [31m[1mWARNING: This is a development server. Do not use it in a production deployment. Use a production WSGI server instead.[0m
 * Running on all addresses (0.0.0.0)
 * Running on http://127.0.0.1:8080
 * Running on http://192.168.40.213:8080
2025-02-08 00:10:39,669 - INFO - [33mPress CTRL+C to quit[0m
2025-02-08 00:10:39,670 - INFO -  * Restarting with stat
2025-02-08 00:10:40,204 - INFO - Found credentials in shared credentials file: ~/.aws/credentials
2025-02-08 00:10:40,512 - WARNING -  * Debugger is active!
2025-02-08 00:10:40,533 - INFO -  * Debugger PIN: 822-635-497
2025-02-08 00:10:55,817 - INFO - User [127.0.0.1] Input: Hello
2025-02-08 00:10:55,824 - INFO - 127.0.0.1 - - [08/Feb/2025 00:10:55] "[35m[1mPOST /api/chat HTTP/1.1[0m" 500 -
2025-02-08 00:13:37,000 - INFO -  * Detected change in '/Users/RyanPierce/Documents/GitHub/Resume/ryanapierce.github.io/assets/projects/about_me_chatbot/backend/application.py', reloading
2025-02-08 00:13:37,114 - INFO -  * Restarting with stat
2025-02-08 00:13:37,737 - INFO - Found credentials in shared credentials file: ~/.aws/credentials
2025-02-08 00:13:38,128 - WARNING -  * Debugger is active!
2025-02-08 00:13:38,151 - INFO -  * Debugger PIN: 822-635-497
2025-02-08 00:13:39,182 - INFO -  * Detected change in '/Users/RyanPierce/Documents/GitHub/Resume/ryanapierce.github.io/assets/projects/about_me_chatbot/backend/application.py', reloading
2025-02-08 00:13:39,277 - INFO -  * Restarting with stat
2025-02-08 00:13:39,789 - INFO - Found credentials in shared credentials file: ~/.aws/credentials
2025-02-08 00:13:40,139 - WARNING -  * Debugger is active!
2025-02-08 00:13:40,160 - INFO -  * Debugger PIN: 822-635-497
